#### 三种状态
- pending resolved rejected
- pending --> resolved || pending --> rejected
- 变化不可逆

#### 状态的表现
- pending 状态，不会触发then和catch
- resolved 状态，会触发后续的then回调函数
- rejected 状态，会触发后续的catch回调函数
- 如果直接需要resolved 或者 rejected 状态，可直接定义Promise.resolved() 或者Promise.rejected()

#### then和catch改变状态
- then正常返回resolved，里面有报错则返回rejected
- catch正常返回resolved，里面有报错则返回rejected

```js
// then() 一般正常返回 resolved 状态的 promise
Promise.resolve().then(() => {
    return 100
})

// then() 里抛出错误，会返回 rejected 状态的 promise
Promise.resolve().then(() => {
    throw new Error('err')
})

// catch() 不抛出错误，会返回 resolved 状态的 promise
Promise.reject().catch(() => {
    console.error('catch some error')
})

// catch() 抛出错误，会返回 rejected 状态的 promise
Promise.reject().catch(() => {
    console.error('catch some error')
    throw new Error('err')
})
```

#### 关于状态变化的题目

```js
// 第一题
Promise.resolve().then(() => {
    console.log(1)      //1
}).catch(() => {
    console.log(2)      
}).then(() => {
    console.log(3)      //3
})

// 第二题
Promise.resolve().then(() => { // 返回 rejected 状态的 promise
    console.log(1)      //1
    throw new Error('erro1')
}).catch(() => { // 返回 resolved 状态的 promise
    console.log(2)      //2
}).then(() => {
    console.log(3)      //3
})

// 第三题
Promise.resolve().then(() => { // 返回 rejected 状态的 promise
    console.log(1)      //1
    throw new Error('erro1')
}).catch(() => { // 返回 resolved 状态的 promise
    console.log(2)      //2
}).catch(() => {
    console.log(3)
})
```